Workbook
Name coef_transmissao: #REF!
Name coeficiente_lockdown: 'SIR Model'!$J$20
Name coeficiente_transmissao: 'SIR Model'!$D$20
Name data_lockdown: 'SIR Model'!$G$17
Name delta_infected: #REF!
Name delta_time: 'SIR Model'!$M$13
Name densidade: 'SIR Model'!$D$15
Name dias_lockdown: 'SIR Model'!$I$12
Name Infected: #REF!
Name infection_rate: 'SIR Model'!$M$9
Name init_infected: 'SIR Model'!$M$12
Name interaction_rate: 'SIR Model'!$M$11
Name model_total: 'SIR Model'!$M$8
Name perc_grupo_risco: 'SIR Model'!$D$13
Name perc_hospitalizado: parametros!$D$25
Name perc_internação: parametros!$D$25
Name percentual_internados: parametros!$D$28
Name pop_total: #REF!
Name populacao_total: 'SIR Model'!$D$9
Name qde_leitos: 'SIR Model'!$D$18
Name recovery_rate: 'SIR Model'!$M$14
Name susceptible: #REF!
Name susceptiveis: 'SIR Model'!$D$10
Name t_remocao: #REF!
Name taxa_de_contato: parametros!$D$12
Name taxa_letalidade: parametros!$D$31
Name taxa_remocao: parametros!$D$21
Name total: #REF!

Sheet Sobre
D2: Versão: | E2: 1.0.0
D3: Data última alteração: | E3: 43933
E5: https://github.com/lcpassuncao/lockdown-simulator
C10: Autores / Colaboradores | D10: e-mail
C12: Luis Assunção | D12: luis_p_assuncao@hotmail.com | E12: https://www.linkedin.com/in/luisassuncao
C13: Jamila Fonseca | D13: jamila.fonseca@hotmail.com | E13: https://www.linkedin.com/in/jamila-fonseca-41b07a19a/

Sheet Referências
B6: REFERÊNCIAS UTILIZADAS NESSE ESTUDO
D8: Página Oficial do Ministério da Saúde
D9: https://coronavirus.saude.gov.br/
D10: https://covid.saude.gov.br/
B13: Modelo SIR em epidemiologia
D15: Tavares, JN (2017) Modelo SIR em epidemiologia, Rev. Ciência Elem., V5(02):020.
D16: https://rce.casadasciencias.org/rceapp/pdf/2017/020/
D17: http://doi.org/10.24927/rce2017.020
D18: https://wikiciencias.casadasciencias.org/wiki/index.php/Modelo_SIR_em_epidemiologia
D21: Aula especial 03/2020 - Covid-19, a Matemática por trás da pandemia - Desafio
D22: Prof. Wagner Santos Escola Livre de Inteligência Artificial
D23: https://www.youtube.com/watch?v=p553vCn9iXA
D24: https://github.com/escolalivre-ia/aulas
D26: Modelo epidêmico. Wikipédia, a enciclopédia livre.
D27: https://pt.wikipedia.org/wiki/Modelo_epid%C3%Aamico
B30: DADOS E INDICADORES - BASE DE DADOS DOS ESTUDOS E PROJEÇÕES
D32: Evolutivo de Casos de Coronavirus - Cidade de São Paulo
D33: https://www.prefeitura.sp.gov.br/cidade/secretarias/saude/
D34: https://www.prefeitura.sp.gov.br/cidade/secretarias/saude/vigilancia_em_saude/doencas_e_agravos/coronavirus/index.php?p=295572
D36: Densidade Demográfica segundo Municípios. Estado de São Paulo, 2000 e 2010.
D37: http://www.saude.sp.gov.br/resources/ses/perfil/gestor/documentos-de-planejamento-em-saude/indicadores-plano-estadual-2012-2015/indicadores/densidade_demografica_2000_e_2010.xls
D39: Proporção da População Idosa (Maiores de 60 anos) segundo os municípios de residência. Estado de São Paulo, 2000 e 2010
D40: http://www.saude.sp.gov.br/resources/ses/perfil/gestor/documentos-de-planejamento-em-saude/indicadores-plano-estadual-2012-2015/indicadores/percentual_da_populacao_idosa_2000_e_2010.xls
D42: Quantidade de Leitos - Rede Hospitalar
D43: http://www.saude.sp.gov.br/resources/ses/perfil/gestor/documentos-de-planejamento-em-saude/indicadores-plano-estadual-2012-2015/indicadores/percentual_da_populacao_idosa_2000_e_2010.xls
D44: http://www.saude.sp.gov.br/resources/ccd/publicacoes/publicacoes-ccd/saude-em-dados/revista_leitos_-_18.pdf
D45: https://www.redesocialdecidades.org.br/br/SP/sao-paulo/leitos-hospitalares

Sheet parametros
B5: PARÂMETROS UTILIZADO NO MODELO DE PROJEÇÃO : S.I.R.
B7: Observação: | D7: <-- Os campos marcados em AMARELO podem ser ajustados
A9: PARÂMETROS INICIAIS DO MODELO S.I.R.
B12: Taxa de contato | D12: 2 | F12: vírus: SARS-CoV-2
B13: (grau de contágio) | F13: ="Ou seja, em 1 dia, cada infectado tem o potencial de transmitir para outras " & taxa_de_contato & " pessoas" -> Ou seja, em 1 dia, cada infectado tem o potencial de transmitir para outras 2 pessoas
F14: Novo coronavírus tem grau de contágio entre 2 e 3
A16: PARÂMETROS de REMOÇÂO DO MODELO S.I.R.
A17: também denomidada de Taxa de Recuperção (inclui o número de mortes)
B20: Período de infecção (dias) | C20: Δt | D20: 3 | F20: tempo médio (em dias) em que um indivíduo é infecioso
B21: Taxa de remoção | C21: g | D21: =1/D20 -> 0.33333333
B25: Percentual de HOSPITALIZADOS: | D25: 0.4 | F25: Percentual do Grupo com Sintomas Médios/Graves que precisam de atendimento HOSPITALAR
B28: Percentual de INTERNADOS | D28: 0.2 | F28: Percentual que permanecem Internados ou Necessitam de Tratamento Intensivo (UTI)
F29: (percentual em relação a quantidade de Hospializados)
B31: Taxa de Letalidade | D31: 0.034 | F31: Percentual de Mortalidade
F32: (nesse estudo esse percentual é aplicado em relação ao número de HOSPITALIZADOS)
A34: PREMISSAS DE CÁLCULO DO PARÂMETRO: (p) - PROBABILIDADE DE CONTÁGIO
A35: OBS: A probabilidade de contágio será variável e proporcional a DENSIDADE POPULACIONAL e ao TIPO DO LOCKDOWN
B38: Valores ESTIMADOS: | C38: PREMISSAS (ajustáveis)
A39: TIPO DO LOCKDOWN | G39: 10 | H39: 32 | I39: 100 | J39: 320 | K39: 1000 | L39: 3200 | M39: 10000
A40: Sem Prevenção | B40: Sem Lockdown | C40: 3 | D40: 18 | G40: =$C40 + $D40 *(LOG10(G$39)-1) -> 3 | H40: =$C40 + $D40 *(LOG10(H$39)-1) -> 12.0927 | I40: =$C40 + $D40 *(LOG10(I$39)-1) -> 21 | J40: =$C40 + $D40 *(LOG10(J$39)-1) -> 30.0927 | K40: =$C40 + $D40 *(LOG10(K$39)-1) -> 39 | L40: =$C40 + $D40 *(LOG10(L$39)-1) -> 48.0927 | M40: =$C40 + $D40 *(LOG10(M$39)-1) -> 57
A41: Afastamento | B41: Distanciamento e Higiene | C41: 2 | D41: 12 | G41: =$C41 + $D41 *(LOG10(G$39)-1) -> 2 | H41: =$C41 + $D41 *(LOG10(H$39)-1) -> 8.0617997 | I41: =$C41 + $D41 *(LOG10(I$39)-1) -> 14 | J41: =$C41 + $D41 *(LOG10(J$39)-1) -> 20.0618 | K41: =$C41 + $D41 *(LOG10(K$39)-1) -> 26 | L41: =$C41 + $D41 *(LOG10(L$39)-1) -> 32.0618 | M41: =$C41 + $D41 *(LOG10(M$39)-1) -> 38
A42: Isolamento Vertical | B42: Isolamento do Grupo Risco | C42: 1 | D42: 9 | G42: =$C42 + $D42 *(LOG10(G$39)-1) -> 1 | H42: =$C42 + $D42 *(LOG10(H$39)-1) -> 5.5463498 | I42: =$C42 + $D42 *(LOG10(I$39)-1) -> 10 | J42: =$C42 + $D42 *(LOG10(J$39)-1) -> 14.54635 | K42: =$C42 + $D42 *(LOG10(K$39)-1) -> 19 | L42: =$C42 + $D42 *(LOG10(L$39)-1) -> 23.54635 | M42: =$C42 + $D42 *(LOG10(M$39)-1) -> 28
A43: Isolamento Horizontal | B43: Isolamento Total | C43: 0.5 | D43: 6 | G43: =$C43 + $D43 *(LOG10(G$39)-1) -> 0.5 | H43: =$C43 + $D43 *(LOG10(H$39)-1) -> 3.5308999 | I43: =$C43 + $D43 *(LOG10(I$39)-1) -> 6.5 | J43: =$C43 + $D43 *(LOG10(J$39)-1) -> 9.5308999 | K43: =$C43 + $D43 *(LOG10(K$39)-1) -> 12.5 | L43: =$C43 + $D43 *(LOG10(L$39)-1) -> 15.5309 | M43: =$C43 + $D43 *(LOG10(M$39)-1) -> 18.5
C49: Coef Trans das Cidades
A50: Exemplos: | C50: EUA-NY | D50: SP-Capital | E50: SP-Lins
B51: Densidade Pop. | C51: 9088 | D51: 8000 | E51: 127
A52: Tipo de Lockdown: | B52: Sem Prevenção | C52: =taxa_de_contato * ($C40 + $D40 *(LOG10(C$51)-1))/100 -> 1.1250486 | D52: =taxa_de_contato * ($C40 + $D40 *(LOG10(D$51)-1))/100 -> 1.1051124 | E52: =taxa_de_contato * ($C40 + $D40 *(LOG10(E$51)-1))/100 -> 0.45736934
B53: Afastamento | C53: =taxa_de_contato * ($C41 + $D41 *(LOG10(C$51)-1))/100 -> 0.7500324 | D53: =taxa_de_contato * ($C41 + $D41 *(LOG10(D$51)-1))/100 -> 0.7367416 | E53: =taxa_de_contato * ($C41 + $D41 *(LOG10(E$51)-1))/100 -> 0.30491289
B54: Isolamento Vertical | C54: =taxa_de_contato * ($C42 + $D42 *(LOG10(C$51)-1))/100 -> 0.5525243 | D54: =taxa_de_contato * ($C42 + $D42 *(LOG10(D$51)-1))/100 -> 0.5425562 | E54: =taxa_de_contato * ($C42 + $D42 *(LOG10(E$51)-1))/100 -> 0.21868467
B55: Isolamento Horizontal | C55: =taxa_de_contato * ($C43 + $D43 *(LOG10(C$51)-1))/100 -> 0.3650162 | D55: =taxa_de_contato * ($C43 + $D43 *(LOG10(D$51)-1))/100 -> 0.3583708 | E55: =taxa_de_contato * ($C43 + $D43 *(LOG10(E$51)-1))/100 -> 0.14245645
G56: OBS1: Esse gráfico demonstra que a probabilidade de contágio aumenta conforme a concentração de pessoas.
G57: OBS2: Dependendo da forma de isolamento, a probabilidade de contágio diminui proporcionalmente com a quantidade mádia de pessoas isoladas
C59: Probabilidade Trans das Cidades
C60: EUA-NY | D60: SP-Capital | E60: SP-Lins
A61: Exemplos: | B61: Densidade Pop. | C61: 9088 | D61: 8000 | E61: 127
A62: Tipo de Lockdown: | B62: Sem Prevenção | C62: =($C40 + $D40 *(LOG10(C$61)-1))/100 -> 0.5625243 | D62: =($C40 + $D40 *(LOG10(D$61)-1))/100 -> 0.5525562 | E62: =($C40 + $D40 *(LOG10(E$61)-1))/100 -> 0.22868467
B63: Afastamento | C63: =($C41 + $D41 *(LOG10(C$61)-1))/100 -> 0.3750162 | D63: =($C41 + $D41 *(LOG10(D$61)-1))/100 -> 0.3683708 | E63: =($C41 + $D41 *(LOG10(E$61)-1))/100 -> 0.15245645
B64: Isolamento Vertical | C64: =($C42 + $D42 *(LOG10(C$61)-1))/100 -> 0.27626215 | D64: =($C42 + $D42 *(LOG10(D$61)-1))/100 -> 0.2712781 | E64: =($C42 + $D42 *(LOG10(E$61)-1))/100 -> 0.10934233
B65: Isolamento Horizontal | C65: =($C43 + $D43 *(LOG10(C$61)-1))/100 -> 0.1825081 | D65: =($C43 + $D43 *(LOG10(D$61)-1))/100 -> 0.1791854 | E65: =($C43 + $D43 *(LOG10(E$61)-1))/100 -> 0.071228223
A68: FÓRMULA EXPONENCIAL UTILIZADA NA PROJEÇÃO DO CRESCIMENTO DA PROBABILIDADE EM RELAÇÃO A DENSIDADE POPULACIONAL
...

Sheet SIR Model
B6: Escolha a: | C6: Cidade/Município: | F6: PARÂMETROS DO SIMULADOR
C7: São Paulo - CAPITAL | F7: Cenários de Isolamento Social
B9: População Total (N) = | D9: =VLOOKUP(C7,'dados-SP'!H10:T654,5,FALSE) -> 12072754
B10: Susceptíveis (S) --> 70% = | D10: =populacao_total*0.7 -> 8450927.8
B11: População Idosos= | D11: =VLOOKUP(C7,'dados-SP'!H10:T654,13,FALSE) -> 1435554 | I11: DIAS
B12: Grupo Risco (80/20) = | D12: =ROUND(100*D11/80,0) -> 1794442 | I12: 31
B13: %Grupo de Risco= | D13: =D12/D9 -> 0.14863568
B15: Densidade Pop (hab/KM2): | D15: =VLOOKUP(C7,'dados-SP'!H10:T654,8,FALSE) -> 8000.4997 | G15: Isolamento Horizontal
G17: 43905
B18: Leitos Disponíveis: | D18: =VLOOKUP(C7,'dados-SP'!H10:U654,14,FALSE) -> 24146
B20: Coeficiente Transmissão (b) | D20: =taxa_de_contato * (parametros!$C$40+ parametros!$D$40 *(LOG10(densidade)-1))/100 -> 1.1051222 | F20: Coeficiente de Transmissão COM Lockdown (b) | J20: =taxa_de_contato * (VLOOKUP(G15,parametros!A40:D43,3,FALSE)+ VLOOKUP(G15,parametros!A40:D43,4,FALSE)*(LOG10(densidade)-1))/100 -> 0.35837405
B21: Núm Básico Reprodução (Ro) | D21: =coeficiente_transmissao/taxa_remocao -> 3.3153665 | F21: Núm Básico de Reprodução COM Lockdown (Ro) | J21: =coeficiente_lockdown/taxa_remocao -> 1.0751222
F23: Total Mortes PROJETADAS no período (120 dias) | J23: =SUM(J26:J149) -> 11632
A25: Time | B25: DATA | C25: Coefic. Transm | D25: Susceptíveis | E25: Infectados | F25: Recuperados | G25: Hospitalizados | H25: Internados | I25: Leitos | J25: Mortes
A26: 0 | B26: 43887 | C26: =IF(AND(B26 > data_lockdown,B26 <= (data_lockdown + dias_lockdown)),coeficiente_lockdown,coeficiente_transmissao) -> 1.1051222 | D26: =susceptiveis-1 -> 8450926.8 | E26: 1 | F26: 0 | G26: =TRUNC(E26*perc_grupo_risco*perc_hospitalizado,0) -> 0 | H26: =G26*percentual_internados -> 0 | I26: =qde_leitos -> 24146
A27: =A26+1 -> 1 | B27: =B26+1 -> 43888 | C27: =IF(AND(B27 > data_lockdown,B27 <= (data_lockdown + dias_lockdown)),coeficiente_lockdown,coeficiente_transmissao) -> 1.1051222 | D27: =MAX(susceptiveis-E27-F27,0) -> 8450926 | E27: =E26+D26*E26*C27/susceptiveis-E26*taxa_remocao -> 1.7717887 | F27: =MIN(ROUND(F26+E26*taxa_remocao,0),susceptiveis) -> 0 | G27: =TRUNC(E27*perc_grupo_risco*perc_hospitalizado,0) -> 0 | H27: =G27*percentual_internados -> 0 | I27: =I26 -> 24146
A28: =A27+1 -> 2 | B28: =B27+1 -> 43889 | C28: =IF(AND(B28 > data_lockdown,B28 <= (data_lockdown + dias_lockdown)),coeficiente_lockdown,coeficiente_transmissao) -> 1.1051222 | D28: =MAX(susceptiveis-E28-F28,0) -> 8450923.7 | E28: =E27+D27*E27*C28/susceptiveis-E27*taxa_remocao -> 3.139235 | F28: =MIN(ROUND(F27+E27*taxa_remocao,0),susceptiveis) -> 1 | G28: =TRUNC(E28*perc_grupo_risco*perc_hospitalizado,0) -> 0 | H28: =G28*percentual_internados -> 0 | I28: =I27 -> 24146
A29: =A28+1 -> 3 | B29: =B28+1 -> 43890 | C29: =IF(AND(B29 > data_lockdown,B29 <= (data_lockdown + dias_lockdown)),coeficiente_lockdown,coeficiente_transmissao) -> 1.1051222 | D29: =MAX(susceptiveis-E29-F29,0) -> 8450920.2 | E29: =E28+D28*E28*C29/susceptiveis-E28*taxa_remocao -> 5.5620598 | F29: =MIN(ROUND(F28+E28*taxa_remocao,0),susceptiveis) -> 2 | G29: =TRUNC(E29*perc_grupo_risco*perc_hospitalizado,0) -> 0 | H29: =G29*percentual_internados -> 0 | I29: =I28 -> 24146
A30: =A29+1 -> 4 | B30: =B29+1 -> 43891 | C30: =IF(AND(B30 > data_lockdown,B30 <= (data_lockdown + dias_lockdown)),coeficiente_lockdown,coeficiente_transmissao) -> 1.1051222 | D30: =MAX(susceptiveis-E30-F30,0) -> 8450913.9 | E30: =E29+D29*E29*C30/susceptiveis-E29*taxa_remocao -> 9.8547899 | F30: =MIN(ROUND(F29+E29*taxa_remocao,0),susceptiveis) -> 4 | G30: =TRUNC(E30*perc_grupo_risco*perc_hospitalizado,0) -> 0 | H30: =G30*percentual_internados -> 0 | I30: =I29 -> 24146
A31: =A30+1 -> 5 | B31: =B30+1 -> 43892 | C31: =IF(AND(B31 > data_lockdown,B31 <= (data_lockdown + dias_lockdown)),coeficiente_lockdown,coeficiente_transmissao) -> 1.1051222 | D31: =MAX(susceptiveis-E31-F31,0) -> 8450903.3 | E31: =E30+D30*E30*C31/susceptiveis-E30*taxa_remocao -> 17.460589 | F31: =MIN(ROUND(F30+E30*taxa_remocao,0),susceptiveis) -> 7 | G31: =TRUNC(E31*perc_grupo_risco*perc_hospitalizado,0) -> 1 | H31: =G31*percentual_internados -> 0.2 | I31: =I30 -> 24146
A32: =A31+1 -> 6 | B32: =B31+1 -> 43893 | C32: =IF(AND(B32 > data_lockdown,B32 <= (data_lockdown + dias_lockdown)),coeficiente_lockdown,coeficiente_transmissao) -> 1.1051222 | D32: =MAX(susceptiveis-E32-F32,0) -> 8450883.9 | E32: =E31+D31*E31*C32/susceptiveis-E31*taxa_remocao -> 30.93642 | F32: =MIN(ROUND(F31+E31*taxa_remocao,0),susceptiveis) -> 13 | G32: =TRUNC(E32*perc_grupo_risco*perc_hospitalizado,0) -> 1 | H32: =G32*percentual_internados -> 0.2 | I32: =I31 -> 24146
A33: =A32+1 -> 7 | B33: =B32+1 -> 43894 | C33: =IF(AND(B33 > data_lockdown,B33 <= (data_lockdown + dias_lockdown)),coeficiente_lockdown,coeficiente_transmissao) -> 1.1051222 | D33: =MAX(susceptiveis-E33-F33,0) -> 8450850 | E33: =E32+D32*E32*C33/susceptiveis-E32*taxa_remocao -> 54.812626 | F33: =MIN(ROUND(F32+E32*taxa_remocao,0),susceptiveis) -> 23 | G33: =TRUNC(E33*perc_grupo_risco*perc_hospitalizado,0) -> 3 | H33: =G33*percentual_internados -> 0.6 | I33: =I32 -> 24146
A34: =A33+1 -> 8 | B34: =B33+1 -> 43895 | C34: =IF(AND(B34 > data_lockdown,B34 <= (data_lockdown + dias_lockdown)),coeficiente_lockdown,coeficiente_transmissao) -> 1.1051222 | D34: =MAX(susceptiveis-E34-F34,0) -> 8450789.7 | E34: =E33+D33*E33*C34/susceptiveis-E33*taxa_remocao -> 97.115841 | F34: =MIN(ROUND(F33+E33*taxa_remocao,0),susceptiveis) -> 41 | G34: =TRUNC(E34*perc_grupo_risco*perc_hospitalizado,0) -> 5 | H34: =G34*percentual_internados -> 1 | I34: =I33 -> 24146
A35: =A34+1 -> 9 | B35: =B34+1 -> 43896 | C35: =IF(AND(B35 > data_lockdown,B35 <= (data_lockdown + dias_lockdown)),coeficiente_lockdown,coeficiente_transmissao) -> 1.1051222 | D35: =MAX(susceptiveis-E35-F35,0) -> 8450682.7 | E35: =E34+D34*E34*C35/susceptiveis-E34*taxa_remocao -> 172.06701 | F35: =MIN(ROUND(F34+E34*taxa_remocao,0),susceptiveis) -> 73 | G35: =TRUNC(E35*perc_grupo_risco*perc_hospitalizado,0) -> 10 | H35: =G35*percentual_internados -> 2 | I35: =I34 -> 24146
A36: =A35+1 -> 10 | B36: =B35+1 -> 43897 | C36: =IF(AND(B36 > data_lockdown,B36 <= (data_lockdown + dias_lockdown)),coeficiente_lockdown,coeficiente_transmissao) -> 1.1051222 | D36: =MAX(susceptiveis-E36-F36,0) -> 8450492.9 | E36: =E35+D35*E35*C36/susceptiveis-E35*taxa_remocao -> 304.86089 | F36: =MIN(ROUND(F35+E35*taxa_remocao,0),susceptiveis) -> 130 | G36: =TRUNC(E36*perc_grupo_risco*perc_hospitalizado,0) -> 18 | H36: =G36*percentual_internados -> 3.6 | I36: =I35 -> 24146
A37: =A36+1 -> 11 | B37: =B36+1 -> 43898 | C37: =IF(AND(B37 > data_lockdown,B37 <= (data_lockdown + dias_lockdown)),coeficiente_lockdown,coeficiente_transmissao) -> 1.1051222 | D37: =MAX(susceptiveis-E37-F37,0) -> 8450155.7 | E37: =E36+D36*E36*C37/susceptiveis-E36*taxa_remocao -> 540.13178 | F37: =MIN(ROUND(F36+E36*taxa_remocao,0),susceptiveis) -> 232 | G37: =TRUNC(E37*perc_grupo_risco*perc_hospitalizado,0) -> 32 | H37: =G37*percentual_internados -> 6.4 | I37: =I36 -> 24146 | J37: =ROUND((D26*E26*C27/populacao_total)*perc_grupo_risco*perc_hospitalizado*taxa_letalidade,0) -> 0
A38: =A37+1 -> 12 | B38: =B37+1 -> 43899 | C38: =IF(AND(B38 > data_lockdown,B38 <= (data_lockdown + dias_lockdown)),coeficiente_lockdown,coeficiente_transmissao) -> 1.1051222 | D38: =MAX(susceptiveis-E38-F38,0) -> 8449558.9 | E38: =E37+D37*E37*C38/susceptiveis-E37*taxa_remocao -> 956.94491 | F38: =MIN(ROUND(F37+E37*taxa_remocao,0),susceptiveis) -> 412 | G38: =TRUNC(E38*perc_grupo_risco*perc_hospitalizado,0) -> 56 | H38: =G38*percentual_internados -> 11.2 | I38: =I37 -> 24146 | J38: =ROUND((D27*E27*C28/populacao_total)*perc_grupo_risco*perc_hospitalizado*taxa_letalidade,0) -> 0
A39: =A38+1 -> 13 | B39: =B38+1 -> 43900 | C39: =IF(AND(B39 > data_lockdown,B39 <= (data_lockdown + dias_lockdown)),coeficiente_lockdown,coeficiente_transmissao) -> 1.1051222 | D39: =MAX(susceptiveis-E39-F39,0) -> 8448501.5 | E39: =E38+D38*E38*C39/susceptiveis-E38*taxa_remocao -> 1695.333 | F39: =MIN(ROUND(F38+E38*taxa_remocao,0),susceptiveis) -> 731 | G39: =TRUNC(E39*perc_grupo_risco*perc_hospitalizado,0) -> 100 | H39: =G39*percentual_internados -> 20 | I39: =I38 -> 24146 | J39: =ROUND((D28*E28*C29/populacao_total)*perc_grupo_risco*perc_hospitalizado*taxa_letalidade,0) -> 0
A40: =A39+1 -> 14 | B40: =B39+1 -> 43901 | C40: =IF(AND(B40 > data_lockdown,B40 <= (data_lockdown + dias_lockdown)),coeficiente_lockdown,coeficiente_transmissao) -> 1.1051222 | D40: =MAX(susceptiveis-E40-F40,0) -> 8446628.6 | E40: =E39+D39*E39*C40/susceptiveis-E39*taxa_remocao -> 3003.2341 | F40: =MIN(ROUND(F39+E39*taxa_remocao,0),susceptiveis) -> 1296 | G40: =TRUNC(E40*perc_grupo_risco*perc_hospitalizado,0) -> 178 | H40: =G40*percentual_internados -> 35.6 | I40: =I39 -> 24146 | J40: =ROUND((D29*E29*C30/populacao_total)*perc_grupo_risco*perc_hospitalizado*taxa_letalidade,0) -> 0
A41: =A40+1 -> 15 | B41: =B40+1 -> 43902 | C41: =IF(AND(B41 > data_lockdown,B41 <= (data_lockdown + dias_lockdown)),coeficiente_lockdown,coeficiente_transmissao) -> 1.1051222 | D41: =MAX(susceptiveis-E41-F41,0) -> 8443311.4 | E41: =E40+D40*E40*C41/susceptiveis-E40*taxa_remocao -> 5319.4083 | F41: =MIN(ROUND(F40+E40*taxa_remocao,0),susceptiveis) -> 2297 | G41: =TRUNC(E41*perc_grupo_risco*perc_hospitalizado,0) -> 316 | H41: =G41*percentual_internados -> 63.2 | I41: =I40 -> 24146 | J41: =ROUND((D30*E30*C31/populacao_total)*perc_grupo_risco*perc_hospitalizado*taxa_letalidade,0) -> 0
A42: =A41+1 -> 16 | B42: =B41+1 -> 43903 | C42: =IF(AND(B42 > data_lockdown,B42 <= (data_lockdown + dias_lockdown)),coeficiente_lockdown,coeficiente_transmissao) -> 1.1051222 | D42: =MAX(susceptiveis-E42-F42,0) -> 8437438.2 | E42: =E41+D41*E41*C42/susceptiveis-E41*taxa_remocao -> 9419.57 | F42: =MIN(ROUND(F41+E41*taxa_remocao,0),susceptiveis) -> 4070 | G42: =TRUNC(E42*perc_grupo_risco*perc_hospitalizado,0) -> 560 | H42: =G42*percentual_internados -> 112 | I42: =I41 -> 24146 | J42: =ROUND((D31*E31*C32/populacao_total)*perc_grupo_risco*perc_hospitalizado*taxa_letalidade,0) -> 0
A43: =A42+1 -> 17 | B43: =B42+1 -> 43904 | C43: =IF(AND(B43 > data_lockdown,B43 <= (data_lockdown + dias_lockdown)),coeficiente_lockdown,coeficiente_transmissao) -> 1.1051222 | D43: =MAX(susceptiveis-E43-F43,0) -> 8427044.9 | E43: =E42+D42*E42*C43/susceptiveis-E42*taxa_remocao -> 16672.873 | F43: =MIN(ROUND(F42+E42*taxa_remocao,0),susceptiveis) -> 7210 | G43: =TRUNC(E43*perc_grupo_risco*perc_hospitalizado,0) -> 991 | H43: =G43*percentual_internados -> 198.2 | I43: =I42 -> 24146 | J43: =ROUND((D32*E32*C33/populacao_total)*perc_grupo_risco*perc_hospitalizado*taxa_letalidade,0) -> 0
A44: =A43+1 -> 18 | B44: =B43+1 -> 43905 | C44: =IF(AND(B44 > data_lockdown,B44 <= (data_lockdown + dias_lockdown)),coeficiente_lockdown,coeficiente_transmissao) -> 1.1051222 | D44: =MAX(susceptiveis-E44-F44,0) -> 8408671.1 | E44: =E43+D43*E43*C44/susceptiveis-E43*taxa_remocao -> 29488.738 | F44: =MIN(ROUND(F43+E43*taxa_remocao,0),susceptiveis) -> 12768 | G44: =TRUNC(E44*perc_grupo_risco*perc_hospitalizado,0) -> 1753 | H44: =G44*percentual_internados -> 350.6 | I44: =I43 -> 24146 | J44: =ROUND((D33*E33*C34/populacao_total)*perc_grupo_risco*perc_hospitalizado*taxa_letalidade,0) -> 0
A45: =A44+1 -> 19 | B45: =B44+1 -> 43906 | C45: =IF(AND(B45 > data_lockdown,B45 <= (data_lockdown + dias_lockdown)),coeficiente_lockdown,coeficiente_transmissao) -> 0.35837405 | D45: =MAX(susceptiveis-E45-F45,0) -> 8398155.5 | E45: =E44+D44*E44*C45/susceptiveis-E44*taxa_remocao -> 30174.314 | F45: =MIN(ROUND(F44+E44*taxa_remocao,0),susceptiveis) -> 22598 | G45: =TRUNC(E45*perc_grupo_risco*perc_hospitalizado,0) -> 1793 | H45: =G45*percentual_internados -> 358.6 | I45: =I44 -> 24146 | J45: =ROUND((D34*E34*C35/populacao_total)*perc_grupo_risco*perc_hospitalizado*taxa_letalidade,0) -> 0
A46: =A45+1 -> 20 | B46: =B45+1 -> 43907 | C46: =IF(AND(B46 > data_lockdown,B46 <= (data_lockdown + dias_lockdown)),coeficiente_lockdown,coeficiente_transmissao) -> 0.35837405 | D46: =MAX(susceptiveis-E46-F46,0) -> 8387409.4 | E46: =E45+D45*E45*C46/susceptiveis-E45*taxa_remocao -> 30862.374 | F46: =MIN(ROUND(F45+E45*taxa_remocao,0),susceptiveis) -> 32656 | G46: =TRUNC(E46*perc_grupo_risco*perc_hospitalizado,0) -> 1834 | H46: =G46*percentual_internados -> 366.8 | I46: =I45 -> 24146 | J46: =ROUND((D35*E35*C36/populacao_total)*perc_grupo_risco*perc_hospitalizado*taxa_letalidade,0) -> 0
A47: =A46+1 -> 21 | B47: =B46+1 -> 43908 | C47: =IF(AND(B47 > data_lockdown,B47 <= (data_lockdown + dias_lockdown)),coeficiente_lockdown,coeficiente_transmissao) -> 0.35837405 | D47: =MAX(susceptiveis-E47-F47,0) -> 8376432.7 | E47: =E46+D46*E46*C47/susceptiveis-E46*taxa_remocao -> 31552.059 | F47: =MIN(ROUND(F46+E46*taxa_remocao,0),susceptiveis) -> 42943 | G47: =TRUNC(E47*perc_grupo_risco*perc_hospitalizado,0) -> 1875 | H47: =G47*percentual_internados -> 375 | I47: =I46 -> 24146 | J47: =ROUND((D36*E36*C37/populacao_total)*perc_grupo_risco*perc_hospitalizado*taxa_letalidade,0) -> 0
A48: =A47+1 -> 22 | B48: =B47+1 -> 43909 | C48: =IF(AND(B48 > data_lockdown,B48 <= (data_lockdown + dias_lockdown)),coeficiente_lockdown,coeficiente_transmissao) -> 0.35837405 | D48: =MAX(susceptiveis-E48-F48,0) -> 8365225.3 | E48: =E47+D47*E47*C48/susceptiveis-E47*taxa_remocao -> 32242.47 | F48: =MIN(ROUND(F47+E47*taxa_remocao,0),susceptiveis) -> 53460 | G48: =TRUNC(E48*perc_grupo_risco*perc_hospitalizado,0) -> 1916 | H48: =G48*percentual_internados -> 383.2 | I48: =I47 -> 24146 | J48: =ROUND((D37*E37*C38/populacao_total)*perc_grupo_risco*perc_hospitalizado*taxa_letalidade,0) -> 1
... A146: =A145+1 -> 120 | B146: =B145+1 -> 44007 | C146: =IF(AND(B146 > data_lockdown,B146 <= (data_lockdown + dias_lockdown)),coeficiente_lockdown,coeficiente_transmissao) -> 1.1051222 | D146: =MAX(susceptiveis-E146-F146,0) -> 229154.8 | E146: =E145+D145*E145*C146/susceptiveis-E145*taxa_remocao -> 0.0016565797 | F146: =MIN(ROUND(F145+E145*taxa_remocao,0),susceptiveis) -> 8221773 | G146: =TRUNC(E146*perc_grupo_risco*perc_hospitalizado,0) -> 0 | H146: =G146*percentual_internados -> 0 | I146: =I145 -> 24146 | J146: =ROUND((D135*E135*C136/populacao_total)*perc_grupo_risco*perc_hospitalizado*taxa_letalidade,0) -> 0

Sheet dados-SP
G5: DADOS UTILIZADOS NO SIMULADOR
H7: ESTADO DE SÃO PAULO | J7: Fonte: | K7: Fonte: | M7: Fonte: | N7: Fonte: | P7: Fonte: | Q7: Fonte: | R7: Fonte: | S7: Fonte: | U7: Fonte:
J8: IBGE | K8: IBGE | M8: IBGE | N8: IBGE | P8: IBGE | Q8: IBGE | R8: IBGE | S8: IBGE | U8: saude.sp.gov.br
A9: UF | B9: C_DRS | C9: DRS | D9: C_RS | E9: REGIÃO SAÚDE | F9: IBGE 6 | G9: IBGE | H9: MUNICÍPIO | I9: Área KM2 2000 | J9: Total População Censo 2000 | K9: Total População Censo 2010 | L9: Total População PROJETADA 2020 | M9: Densidade Demográfica 2000 | N9: Densidade Demográfica 2010 | O9: Densidade PROJETADA 2020 | P9: POPULAÇÃO IDOSA 2000 | Q9: POPULAÇÃO IDOSA 2010 | R9: PROPORÇÃO IDOSOS 2000 | S9: PROPORÇÃO IDOSOS 2010 | T9: População IDOSA PROJETADA 2020 | U9: Leitos Disponíveis ESTIMADO 2 : 1000 hab
A10: SP | B10: 3501 | C10: GRANDE S. PAULO | D10: 35017 | E10: SÃO PAULO | F10: 355030 | G10: 3550308 | H10: São Paulo - CAPITAL | I10: 1509 | J10: 10434252 | K10: 11253503 | L10: =IF(K10>J10,(K10-J10)+K10,K10) -> 12072754 | M10: 6914.6799 | N10: 7457.5898 | O10: =L10/I10 -> 8000.4997 | P10: 972199 | Q10: 1338138 | R10: 9.3173809 | S10: 11.890857 | T10: =(S10/100)*L10 -> 1435554 | U10: =ROUND(2*L10/1000,0) -> 24146
A11: SP | B11: 3509 | C11: MARÍLIA | D11: 35091 | E11: ADAMANTINA | F11: 350010 | G11: 3500105 | H11: Adamantina | I11: 428 | J11: 33497 | K11: 33797 | L11: =IF(K11>J11,(K11-J11)+K11,K11) -> 34097 | M11: 78.264019 | N11: 78.964953 | O11: =L11/I11 -> 79.665888 | P11: 4670 | Q11: 5933 | R11: 13.941547 | S11: 17.554813 | T11: =(S11/100)*L11 -> 5985.6644 | U11: =ROUND(2*L11/1000,0) -> 68
A12: SP | B12: 3515 | C12: S. JOSÉ R. PRETO | D12: 35156 | E12: JOSÉ BONIFÁCIO | F12: 350020 | G12: 3500204 | H12: Adolfo | I12: 218 | J12: 3684 | K12: 3557 | L12: =IF(K12>J12,(K12-J12)+K12,K12) -> 3557 | M12: 16.899083 | N12: 16.316514 | O12: =L12/I12 -> 16.316514 | P12: 429 | Q12: 565 | R12: 11.644951 | S12: 15.884172 | T12: =(S12/100)*L12 -> 565 | U12: =ROUND(2*L12/1000,0) -> 7
A13: SP | B13: 3514 | C13: S. JOÃO B. VISTA | D13: 35142 | E13: MANTIQUEIRA | F13: 350030 | G13: 3500303 | H13: Aguaí | I13: 462 | J13: 28195 | K13: 32148 | L13: =IF(K13>J13,(K13-J13)+K13,K13) -> 36101 | M13: 61.028139 | N13: 69.584416 | O13: =L13/I13 -> 78.140693 | P13: 2862 | Q13: 3777 | R13: 10.150736 | S13: 11.748787 | T13: =(S13/100)*L13 -> 4241.4295 | U13: =ROUND(2*L13/1000,0) -> 72
A14: SP | B14: 3514 | C14: S. JOÃO B. VISTA | D14: 35142 | E14: MANTIQUEIRA | F14: 350040 | G14: 3500402 | H14: Águas da Prata | I14: 155 | J14: 7131 | K14: 7584 | L14: =IF(K14>J14,(K14-J14)+K14,K14) -> 8037 | M14: 46.006452 | N14: 48.929032 | O14: =L14/I14 -> 51.851613 | P14: 1093 | Q14: 1404 | R14: 15.327444 | S14: 18.512658 | T14: =(S14/100)*L14 -> 1487.8623 | U14: =ROUND(2*L14/1000,0) -> 16
A15: SP | B15: 3507 | C15: CAMPINAS | D15: 35072 | E15: CAMPINAS | F15: 350050 | G15: 3500501 | H15: Águas de Lindóia | I15: 64 | J15: 16190 | K15: 17266 | L15: =IF(K15>J15,(K15-J15)+K15,K15) -> 18342 | M15: 252.96875 | N15: 269.78125 | O15: =L15/I15 -> 286.59375 | P15: 1961 | Q15: 2616 | R15: 12.112415 | S15: 15.151164 | T15: =(S15/100)*L15 -> 2779.0265 | U15: =ROUND(2*L15/1000,0) -> 37
A16: SP | B16: 3506 | C16: BAURU | D16: 35061 | E16: AVARÉ | F16: 350055 | G16: 3500550 | H16: Águas de Santa Bárbara | I16: 416 | J16: 5224 | K16: 5601 | L16: =IF(K16>J16,(K16-J16)+K16,K16) -> 5978 | M16: 12.557692 | N16: 13.463942 | O16: =L16/I16 -> 14.370192 | P16: 619 | Q16: 835 | R16: 11.849158 | S16: 14.908052 | T16: =(S16/100)*L16 -> 891.20336 | U16: =ROUND(2*L16/1000,0) -> 12
A17: SP | B17: 3510 | C17: PIRACICABA | D17: 35103 | E17: PIRACICABA | F17: 350060 | G17: 3500600 | H17: Águas de São Pedro | I17: 3 | J17: 1883 | K17: 2707 | L17: =IF(K17>J17,(K17-J17)+K17,K17) -> 3531 | M17: 627.66667 | N17: 902.33333 | O17: =L17/I17 -> 1177 | P17: 386 | Q17: 673 | R17: 20.499203 | S17: 24.86147 | T17: =(S17/100)*L17 -> 877.85851 | U17: =ROUND(2*L17/1000,0) -> 7
A18: SP | B18: 3506 | C18: BAURU | D18: 35062 | E18: BAURU | F18: 350070 | G18: 3500709 | H18: Agudos | I18: 955 | J18: 32484 | K18: 34524 | L18: =IF(K18>J18,(K18-J18)+K18,K18) -> 36564 | M18: 34.01466 | N18: 36.150785 | O18: =L18/I18 -> 38.286911 | P18: 2854 | Q18: 3920 | R18: 8.7858638 | S18: 11.35442 | T18: =(S18/100)*L18 -> 4151.6302 | U18: =ROUND(2*L18/1000,0) -> 73
A19: SP | B19: 3516 | C19: SOROCABA | D19: 35161 | E19: ITAPETININGA | F19: 350075 | G19: 3500758 | H19: Alambari | I19: 173 | J19: 3650 | K19: 4884 | L19: =IF(K19>J19,(K19-J19)+K19,K19) -> 6118 | M19: 21.098266 | N19: 28.231214 | O19: =L19/I19 -> 35.364162 | P19: 347 | Q19: 571 | R19: 9.5068493 | S19: 11.691237 | T19: =(S19/100)*L19 -> 715.26986 | U19: =ROUND(2*L19/1000,0) -> 12
A20: SP | B20: 3511 | C20: PRESIDENTE PRUDENTE | D20: 35112 | E20: ALTA SOROCABANA | F20: 350080 | G20: 3500808 | H20: Alfredo Marcondes | I20: 136 | J20: 3697 | K20: 3891 | L20: =IF(K20>J20,(K20-J20)+K20,K20) -> 4085 | M20: 27.183824 | N20: 28.610294 | O20: =L20/I20 -> 30.036765 | P20: 549 | Q20: 790 | R20: 14.849878 | S20: 20.303264 | T20: =(S20/100)*L20 -> 829.38833 | U20: =ROUND(2*L20/1000,0) -> 8
A21: SP | B21: 3505 | C21: BARRETOS | D21: 35051 | E21: NORTE-BARRETOS | F21: 350090 | G21: 3500907 | H21: Altair | I21: 338 | J21: 3530 | K21: 3815 | L21: =IF(K21>J21,(K21-J21)+K21,K21) -> 4100 | M21: 10.443787 | N21: 11.286982 | O21: =L21/I21 -> 12.130178 | P21: 306 | Q21: 418 | R21: 8.6685552 | S21: 10.95675 | T21: =(S21/100)*L21 -> 449.22674 | U21: =ROUND(2*L21/1000,0) -> 8
... A654: SP | B654: 3514 | C654: S. JOÃO B. VISTA | D654: 35141 | E654: BAIXA MOGIANA | F654: 355730 | G654: 3557303 | H654: Estiva Gerbi | I654: 74 | J654: 8856 | K654: 10044 | L654: =IF(K654>J654,(K654-J654)+K654,K654) -> 11232 | M654: 119.67568 | N654: 135.72973 | O654: =L654/I654 -> 151.78378 | P654: 710 | Q654: 1015 | R654: 8.0171635 | S654: 10.105536 | T654: =(S654/100)*L654 -> 1135.0538 | U654: =ROUND(2*L654/1000,0) -> 22

Sheet comparativo
C5: Referência | D5: https://www.prefeitura.sp.gov.br/cidade/secretarias/saude/vigilancia_em_saude/doencas_e_agravos/coronavirus/index.php?p=295572
B7: DADOS REAIS - SECRETARIA SAÚDE SP | G7: DADOS PROJETADOS NO SIMULADOR
B8: Município de São Paulo | G8: Município de São Paulo
B9: Data de fechamento do dado | C9: Número de casos suspeitos | D9: Número de casos confirmados | E9: Números de Óbitos Acumulados | G9: data | H9: Isolamento | I9: Coefic. Transm | J9: Infectados | K9: Hospitalizados | L9: Mortes por Dia | M9: Mortes Projetadas | O9: Desvio
G10: 43887 | H10: sem isolamento | I10: 1.1051222 | J10: 1 | K10: 0 | M10: 0
G11: 43888 | H11: sem isolamento | I11: 1.1051222 | J11: 2 | K11: 0 | M11: =M10+L11 -> 0
G12: 43889 | H12: sem isolamento | I12: 1.1051222 | J12: 4 | K12: 0 | M12: =M11+L12 -> 0
G13: 43890 | H13: sem isolamento | I13: 1.1051222 | J13: 7 | K13: 0 | M13: =M12+L13 -> 0
G14: 43891 | H14: sem isolamento | I14: 1.1051222 | J14: 12 | K14: 0 | M14: =M13+L14 -> 0
G15: 43892 | H15: sem isolamento | I15: 1.1051222 | J15: 21 | K15: 1 | M15: =M14+L15 -> 0
G16: 43893 | H16: sem isolamento | I16: 1.1051222 | J16: 37 | K16: 1 | M16: =M15+L16 -> 0
G17: 43894 | H17: sem isolamento | I17: 1.1051222 | J17: 66 | K17: 3 | M17: =M16+L17 -> 0
G18: 43895 | H18: sem isolamento | I18: 1.1051222 | J18: 117 | K18: 5 | M18: =M17+L18 -> 0
G19: 43896 | H19: sem isolamento | I19: 1.1051222 | J19: 207 | K19: 10 | M19: =M18+L19 -> 0
G20: 43897 | H20: sem isolamento | I20: 1.1051222 | J20: 367 | K20: 18 | M20: =M19+L20 -> 0
G21: 43898 | H21: sem isolamento | I21: 1.1051222 | J21: 650 | K21: 31 | L21: 0 | M21: =M20+L21 -> 0
G22: 43899 | H22: sem isolamento | I22: 1.1051222 | J22: 1152 | K22: 56 | L22: 0 | M22: =M21+L22 -> 0
G23: 43900 | H23: sem isolamento | I23: 1.1051222 | J23: 2041 | K23: 100 | L23: 0 | M23: =M22+L23 -> 0
G24: 43901 | H24: sem isolamento | I24: 1.1051222 | J24: 3615 | K24: 177 | L24: 0 | M24: =M23+L24 -> 0
G25: 43902 | H25: sem isolamento | I25: 1.1051222 | J25: 6403 | K25: 314 | L25: 0 | M25: =M24+L25 -> 0
G26: 43903 | H26: sem isolamento | I26: 1.1051222 | J26: 11337 | K26: 556 | L26: 0 | M26: =M25+L26 -> 0
G27: 43904 | H27: sem isolamento | I27: 1.1051222 | J27: 20063 | K27: 984 | L27: 0 | M27: =M26+L27 -> 0
G28: 43905 | H28: sem isolamento | I28: 1.1051222 | J28: 35472 | K28: 1739 | L28: 0 | M28: =M27+L28 -> 0
G29: 43906 | H29: HORIZONTAL | I29: 0.35837405 | J29: 36284 | K29: 1779 | L29: 0 | M29: =M28+L29 -> 0
G30: 43907 | H30: HORIZONTAL | I30: 0.35837405 | J30: 37095 | K30: 1819 | L30: 0 | M30: =M29+L30 -> 0
G31: 43908 | H31: HORIZONTAL | I31: 0.35837405 | J31: 37904 | K31: 1859 | L31: 1 | M31: =M30+L31 -> 1
G32: 43909 | H32: HORIZONTAL | I32: 0.35837405 | J32: 38709 | K32: 1898 | L32: 1 | M32: =M31+L32 -> 2
... G35: 43912 | H35: HORIZONTAL | I35: 0.35837405 | J35: 41089 | K35: 2015 | L35: 6 | M35: =M34+L35 -> 13
B36: 43913 | C36: 4743 | D36: 477 | E36: 30 | G36: 43913 | H36: HORIZONTAL | I36: 0.35837405 | J36: 41865 | K36: 2053 | L36: 10 | M36: =M35+L36 -> 23 | O36: =ABS((M36-E36)/E36) -> 0.23333333
B37: 43914 | C37: 4572 | D37: 484 | E37: 36 | G37: 43914 | H37: HORIZONTAL | I37: 0.35837405 | J37: 42630 | K37: 2090 | L37: 18 | M37: =M36+L37 -> 41 | O37: =ABS((M37-E37)/E37) -> 0.13888889
B38: 43915 | C38: 4300 | D38: 537 | E38: 41 | G38: 43915 | H38: HORIZONTAL | I38: 0.35837405 | J38: 43383 | K38: 2127 | L38: 31 | M38: =M37+L38 -> 72 | O38: =ABS((M38-E38)/E38) -> 0.75609756
B39: 43916 | C39: 4621 | D39: 565 | E39: 50 | G39: 43916 | H39: HORIZONTAL | I39: 0.35837405 | J39: 44122 | K39: 2164 | L39: 18 | M39: =M38+L39 -> 90 | O39: =ABS((M39-E39)/E39) -> 0.8
G40: 43917 | H40: HORIZONTAL | I40: 0.35837405 | J40: 44845 | K40: 2199 | L40: 18 | M40: =M39+L40 -> 108
G41: 43918 | H41: HORIZONTAL | I41: 0.35837405 | J41: 45550 | K41: 2234 | L41: 19 | M41: =M40+L41 -> 127
G42: 43919 | H42: HORIZONTAL | I42: 0.35837405 | J42: 46236 | K42: 2267 | L42: 19 | M42: =M41+L42 -> 146
B43: 43920 | C43: 4311 | D43: 593 | E43: 100 | G43: 43920 | H43: HORIZONTAL | I43: 0.35837405 | J43: 46901 | K43: 2300 | L43: 19 | M43: =M42+L43 -> 165 | O43: =ABS((M43-E43)/E43) -> 0.65
B44: 43921 | C44: 8274 | D44: 1438 | E44: 118 | G44: 43921 | H44: HORIZONTAL | I44: 0.35837405 | J44: 47544 | K44: 2332 | L44: 20 | M44: =M43+L44 -> 185 | O44: =ABS((M44-E44)/E44) -> 0.56779661
B45: 43922 | C45: 8551 | D45: 1503 | E45: 141 | G45: 43922 | H45: HORIZONTAL | I45: 0.35837405 | J45: 48163 | K45: 2362 | L45: 20 | M45: =M44+L45 -> 205 | O45: =ABS((M45-E45)/E45) -> 0.45390071
B46: 43923 | C46: 8003 | D46: 1520 | E46: 165 | G46: 43923 | H46: HORIZONTAL | I46: 0.35837405 | J46: 48756 | K46: 2391 | L46: 20 | M46: =M45+L46 -> 225 | O46: =ABS((M46-E46)/E46) -> 0.36363636
B47: 43924 | C47: 7275 | D47: 2321 | E47: 180 | G47: 43924 | H47: HORIZONTAL | I47: 0.35837405 | J47: 49322 | K47: 2419 | L47: 21 | M47: =M46+L47 -> 246 | O47: =ABS((M47-E47)/E47) -> 0.36666667
...

Sheet rank Densidade
C5: RANKING DAS DENSIDADES DEMOGRÁFICAS
A7: MAIORES DENSIDADES POP. - ESTADO DE SP | F7: MENORES DENSIDADES POP. - ESTADO DE SP
A8: Rank | B8: MUNICÍPIO | C8: População | D8: Densidade | F8: Rank | G8: MUNICÍPIO | H8: População | I8: Densidade
A9: 1 | B9: Taboão da Serra | C9: 291412 | D9: 14570 | F9: 1 | G9: Iporanga | H9: 4299 | I9: 3
A10: 2 | B10: São Caetano do Sul | C10: 158367 | D10: 13197 | F10: 2 | G10: Lutécia | H10: 2714 | I10: 5
A11: 3 | B11: Diadema | C11: 415114 | D11: 12972 | F11: 3 | G11: Marabá Paulista | H11: 5925 | I11: 6
A12: 4 | B12: Carapicuíba | C12: 394572 | D12: 10960 | F12: 4 | G12: Nova Castilho | H12: 1259 | I12: 6
A13: 5 | B13: Osasco | C13: 680887 | D13: 10013 | F13: 5 | G13: Santo Antônio do Aracanguá | H13: 8323 | I13: 6
A14: 6 | B14: São Paulo - CAPITAL | C14: 12072754 | D14: 8000 | F14: 6 | G14: São José do Barreiro | H14: 4077 | I14: 6
A15: 7 | B15: Ferraz de Vasconcelos | C15: 194235 | D15: 7769 | F15: 7 | G15: Arco-Íris | H15: 1925 | I15: 7
A16: 8 | B16: Mauá | C16: 470736 | D16: 7025 | F16: 8 | G16: Barra do Turvo | H16: 7729 | I16: 7
A17: 9 | B17: Poá | C17: 116225 | D17: 6836 | F17: 9 | G17: Borá | H17: 815 | I17: 7
A18: 10 | B18: Jandira | C18: 124881 | D18: 5676 | F18: 10 | G18: Borebi | H18: 2653 | I18: 7
A19: 11 | B19: Barueri | C19: 273217 | D19: 4478 | F19: 11 | G19: Flora Rica | H19: 1752 | I19: 7
A20: 12 | B20: Itaquaquecetuba | C20: 370598 | D20: 4465 | F20: 12 | G20: Natividade da Serra | H20: 6678 | I20: 7
... A330: 322 | B330: São Bento do Sapucaí | C330: 10581 | D330: 41 | F330: 322 | G330: Terra Roxa | H330: 9258 | I330: 40
A331: 323 | B331: Taiúva | C331: 5447 | D331: 41

Sheet Prox Passos
B6: PRÓXIMOS PASSOS - SUGESTÕES DE CONTINUIDADE DE ESTUDO
B8: 1 | C8: Simular com Novos Estados/Cidades | D8: Ampliar o estudo do Modelo SIR para o restantes dos Estados e Municípios (além do estado de SP)
B9: 2 | C9: Ajustes Finos - Acompanhamento | D9: Acompanhar a evolução dos números reais e eventualmente realizar ajustes finos nos parâmetros com a finalidade de aumentar a acurácia
B10: 3 | C10: Comparação Global | D10: Incluir no estudo cidades (com dados relevantes) de outros países, e gerar gráficos comportamentais, através de modelos de segmentação / clusterização
B11: 4 | C11: Impatos Sociais do LockDown | D11: Estudo de correlação do aumento de casos de violência doméstica nos períodos de Lockdown
B12: 5 | C12: Impatos Sociais do LockDown | D12: Estudo de correlação do aumento da violência urbana (furtos e homicídios) no período de Lockdown
B13: 6 | C13: Impatos Sociais do LockDown | D13: Estudo de correlação do aumento mortes (por outras motivações como fome e outras enfermidades) na população mais carente
B14: 7 | C14: Impatos Sociais do LockDown | D14: Estudo de correlação do aumento de suicídios nos períodos de loackdown. Associar tb com o índice de desemprego
B15: 8 | C15: Impactos Economicos do Lockdown | D15: Estudo de correlação do indice de desemprego com os períodos de Lockdown
